<mujoco model="aubo_i5">
  <compiler angle="radian"/>

  <asset>
    <material name="orange" rgba="0.996 0.369 0.063 1" specular="0.5" shininess="0.5"/>
    <material name="black" rgba="0 0 0 1" specular="0.8" shininess="0.8"/>
    <mesh name="base_link" file="../models/base_link.STL"/>
    <mesh name="shoulder_Link" file="../models/shoulder_Link.STL"/>
    <mesh name="upperArm_Link" file="../models/upperArm_Link.STL"/>
    <mesh name="foreArm_Link" file="../models/foreArm_Link.STL"/>
    <mesh name="wrist1_Link" file="../models/wrist1_Link.STL"/>
    <mesh name="wrist2_Link" file="../models/wrist2_Link.STL"/>
    <mesh name="wrist3_Link" file="../models/wrist3_Link.STL"/>
  </asset>

  <worldbody>
    <geom type="mesh" rgba="1 1 1 1" mesh="base_link"/>
    <body name="shoulder_Link" pos="0 0 0.122" quat="-3.67321e-06 0 0 1">
      <inertial pos="3.25089e-07 0.00534955 -0.00883689" quat="0.99587 -0.0907855 0 0" mass="1.57658" diaginertia="0.00406404 0.00395808 0.00305754"/>
      <joint name="shoulder_joint" pos="0 0 0" axis="0 0 1" range="-3.04 3.04"/>
      <geom type="mesh" rgba="1 1 1 1" mesh="shoulder_Link"/>
      <body name="upperArm_Link" pos="0 0.1215 0" quat="0.499998 -0.5 -0.5 -0.500002">
        <inertial pos="0.203997 2.01305e-10 0.0127642" quat="0.5 0.5 0.5 0.5" mass="4.04176" diaginertia="0.144994 0.142607 0.00965399"/>
        <joint name="upperArm_joint" pos="0 0 0" axis="0 0 1" range="-3.04 3.04"/>
        <geom type="mesh" rgba="1 1 1 1" mesh="upperArm_Link"/>
        <body name="foreArm_Link" pos="0.408 0 0" quat="-3.67321e-06 -1 0 0">
          <inertial pos="0.188922 6.78882e-07 0.0981027" quat="0.504333 0.495629 0.495629 0.504333" mass="2.27146" diaginertia="0.0443926 0.0441401 0.00213049"/>
          <joint name="foreArm_joint" pos="0 0 0" axis="0 0 1" range="-3.04 3.04"/>
          <geom type="mesh" rgba="1 1 1 1" mesh="foreArm_Link"/>
          <body name="wrist1_Link" pos="0.376 0 0" quat="-2.59734e-06 0.707105 0.707108 -2.59735e-06">
            <inertial pos="7.54205e-07 0.00624813 -0.00392367" quat="0.677608 0.735423 0 0" mass="0.500478" diaginertia="0.000711946 0.000687466 0.000403991"/>
            <joint name="wrist1_joint" pos="0 0 0" axis="0 0 1" range="-3.04 3.04"/>
            <geom type="mesh" rgba="1 1 1 1" mesh="wrist1_Link"/>
            <body name="wrist2_Link" pos="0 0.1025 0" quat="0.707105 -0.707108 0 0">
              <inertial pos="-7.54208e-07 -0.00624813 -0.00392367" quat="0.735423 0.677608 0 0" mass="0.500478" diaginertia="0.000711946 0.000687466 0.000403991"/>
              <joint name="wrist2_joint" pos="0 0 0" axis="0 0 1" range="-3.04 3.04"/>
              <geom type="mesh" rgba="1 1 1 1" mesh="wrist2_Link"/>
              <body name="wrist3_Link" pos="0 -0.094 0" quat="0.707105 0.707108 0 0">
                <inertial pos="3.92049e-10 0.000175788 -0.0213294" quat="0.5 0.5 -0.5 0.5" mass="0.15831" diaginertia="0.000108772 7.31376e-05 7.19528e-05"/>
                <joint name="wrist3_joint" pos="0 0 0" axis="0 0 1" range="-3.04 3.04"/>
                <geom type="mesh" rgba="1 1 1 1" mesh="wrist3_Link"/>
              </body>
            </body>
          </body>
        </body>
      </body>
    </body>
  </worldbody>
</mujoco>
